<?xml version="1.0"?>
<robot xmlns:xacro="http://www.ros.org/wiki/xacro"  name="robot">

    <material name = "white">
        <color rgba = "1 1 1 1" />  
    </material>

    <material name = "black">
        <color rgba = "0 0 0 1" />  
    </material>

    <material name = "orange">
        <color rgba = "1 0.3 0.1 1" />  
    </material>

    <!-- base link -->
    <link name = "base_link">

    </link>

    <joint name = "base_link" type = "fixed">
        <parent link = "base_link"/>
        <child link = "body"/>
        <origin xyz = "-0.1 0 0"/>
    </joint>

    <!-- body link -->

    <link name = "body">
        <visual>
            <origin xyz = "0.135 0 0.07"/>
            <geometry>
                <box size = "0.27 0.168 0.14" /> 
            </geometry>
            
            <material name = "white"/>
        </visual>
    </link>

    <!-- right wheel link -->

    <joint name = "r_wheel_joint" type = "continuous">
        <parent link = "base_link"/>
        <child link = "r_wheel"/>
        <origin xyz = "0.09647 -0.1025 0.01727" rpy = "${pi/2} 0 0"/>
        <axis xyz = "0 0 -1"/>
    </joint>

    <link name = "r_wheel">
        <visual>    
            <geometry>
                <cylinder radius = "0.04" length = "0.037"/>
            </geometry>
            <material name = "black"/>
        </visual>
    </link>


    <!-- left wheel link -->

    <joint name = "l_wheel_joint" type = "continuous">
        <parent link = "base_link"/>
        <child link = "l_wheel"/>
        <origin xyz = "0.09647 0.1025 0.01727" rpy = "-${pi/2} 0 0"/>
        <axis xyz = "0 0 1"/>
    </joint>

    <link name = "l_wheel">
        <visual>    
            <geometry>
                <cylinder radius = "0.04" length = "0.037"/>
            </geometry>
            <material name = "black"/>
        </visual>
    </link>

</robot>